<?xml version='1.0' encoding='utf-8'?>
<mujocoinclude model="ProHand_V18R" name="ProHand_V18R">
    <!--
        ==============================================================================================================================
        |                                                    Generation Metadata                                                     |
        ==============================================================================================================================
        | Field           | Value                                                                                                    |
        ==============================================================================================================================
        | Generated on    | 2025-07-31 15:44:00 UTC                                                                                  |
        | Repository      | fusion-to-sim-models                                                                                     |
        | Remote URL      | git@github.com.jack:Proception-AI/fusion-to-sim-models                                                   |
        | Branch          | user/jack/refactor/separate_raw_export                                                                   |
        | Commit          | 4af123674594                                                                                             |
        | Generated by    | jack-proception                                                                                          |
        | Generator       | fusion_to_sim_model                                                                                      |
        | Generator class | YamlRobot                                                                                                |
        | Description     | (Post-processing (<class 'core.post.yaml_robot.YamlTree'>) based on YAML Robot Description Files [YRDF]) |
        ==============================================================================================================================
    -->
    <body name="R/forearm1" pos="0.0000000 0.0000000 0.0000000" quat="1e+00 0e+00 0e+00 0e+00">
        <inertial mass="3.9427676" pos="0.0043528 0.0000449 0.1073299" diaginertia="1.526145e-02 1.522456e-02 4.313841e-03" />
        <geom name="R/forearm1/visual" class="visual" mesh="gen_1_8_R_description/optimized/forearm1" />
        <geom name="R/forearm1/collision" class="collision" mesh="gen_1_8_R_description/convex/forearm1" />
        <body name="R/wrist_base_link_1" pos="0.0050000 0.0010000 0.2183000" quat="6.123e-17 -0e+00 0e+00 1e+00">
            <inertial mass="0.0598453" pos="0.0000027 0.0000166 0.0074329" diaginertia="7.91751e-06 1.003025e-05 1.142026e-05" />
            <geom name="R/wrist_base_link_1/visual" class="visual" mesh="gen_1_8_R_description/optimized/wrist_base_link_1" />
            <geom name="R/wrist_base_link_1/collision" class="collision" mesh="gen_1_8_R_description/convex/wrist_base_link_1" />
            <body name="R/yaw_body1" pos="0.0000000 -0.0000000 0.0200000" quat="0e+00 7.071068e-01 0e+00 7.071068e-01">
                <inertial mass="0.0893144" pos="0.0102605 0.0000213 0.0030975" diaginertia="2.136406e-05 1.967471e-05 2.998291e-05" />
                <geom name="R/yaw_body1/visual" class="visual" mesh="gen_1_8_R_description/optimized/yaw_body1" />
                <geom name="R/yaw_body1/collision" class="collision" mesh="gen_1_8_R_description/convex/yaw_body1" />
                <joint name="R/wrist_yaw" axis="0 0 1" pos="0 0 0" range="-5.235988e-01 5.235988e-01" limited="true" />
                <body name="R/palm1" pos="0.0195000 0.0000000 0.0050000" quat="5e-01 5e-01 5e-01 -5e-01">
                    <inertial mass="0.7491704" pos="0.0002088 0.0516383 -0.0023448" diaginertia="1.025055e-03 4.307395e-04 7.16861e-04" />
                    <geom name="R/palm1/visual" class="visual" mesh="gen_1_8_R_description/optimized/palm1" />
                    <geom name="R/palm1/collision" class="collision" mesh="gen_1_8_R_description/convex/palm1" />
                    <joint name="R/wrist_pitch" axis="0 0 1" pos="0 0 0" range="-5.235988e-01 1.047198e+00" limited="true" />
                    <body name="R/meta_base_link_1" pos="-0.0010000 0.0930000 -0.0320000" quat="-7.071068e-01 -1.4943e-16 7.071068e-01 -4.7593e-16">
                        <inertial mass="0.0044634" pos="-0.0000002 0.0037355 -0.0003225" diaginertia="1.474219e-07 1.333687e-07 1.205535e-07" />
                        <geom name="R/meta_base_link_1/visual" class="visual" mesh="gen_1_8_R_description/optimized/meta_base_link_1" />
                        <geom name="R/meta_base_link_1/collision" class="collision" mesh="gen_1_8_R_description/convex/meta_base_link_1" />
                        <joint name="R/p0_CMC_abd" axis="0 0 1" pos="0 0 0" range="-6.108652e-01 2.617994e-01" limited="true" />
                        <body name="R/prox_body1" pos="0.0000000 0.0070000 -0.0000120" quat="0e+00 7.071068e-01 0e+00 7.071068e-01">
                            <inertial mass="0.0210231" pos="0.0030714 -0.0174744 -0.0000006" diaginertia="1.47529e-06 9.286679e-07 1.244961e-06" />
                            <geom name="R/prox_body1/visual" class="visual" mesh="gen_1_8_R_description/optimized/prox_body1" />
                            <geom name="R/prox_body1/collision" class="collision" mesh="gen_1_8_R_description/convex/prox_body1" />
                            <joint name="R/p1_MCP" axis="0 0 1" pos="0 0 0" range="-3.490658e-01 1.570796e+00" limited="true" />
                            <body name="R/m_body1" pos="0.0000000 -0.0320000 -0.0000000" quat="1e+00 1.3796e-16 -1.1102e-16 -4e-20">
                                <inertial mass="0.0050835" pos="0.0018313 -0.0112756 -0.0000000" diaginertia="3.539997e-07 1.518711e-07 3.039656e-07" />
                                <geom name="R/m_body1/visual" class="visual" mesh="gen_1_8_R_description/optimized/m_body1" />
                                <geom name="R/m_body1/collision" class="collision" mesh="gen_1_8_R_description/convex/m_body1" />
                                <joint name="R/p2_PIP" axis="0 0 1" pos="0 0 0" range="-2.617994e-01 1.570796e+00" limited="true" />
                                <body name="R/dist_body1" pos="0.0040000 -0.0200000 -0.0000000" quat="1e+00 2.963e-17 0e+00 -1.384e-17">
                                    <inertial mass="0.0059230" pos="-0.0016616 -0.0128501 0.0000005" diaginertia="4.257244e-07 1.446234e-07 4.098516e-07" />
                                    <geom name="R/dist_body1/visual" class="visual" mesh="gen_1_8_R_description/optimized/dist_body1" />
                                    <geom name="R/dist_body1/collision" class="collision" mesh="gen_1_8_R_description/convex/dist_body1" />
                                    <joint name="R/p3_DIP" axis="0 0 1" pos="0 0 0" range="0e+00 1.570796e+00" limited="true" />
                                </body>
                            </body>
                        </body>
                    </body>
                    <body name="R/t" pos="-0.0100000 0.0395289 0.0235680" quat="1.59712e-15 -1.87099e-15 -5.735764e-01 8.19152e-01">
                        <inertial mass="0.0231931" pos="-0.0005379 -0.0028578 -0.0008761" diaginertia="1.870542e-06 1.614859e-06 1.25586e-06" />
                        <geom name="R/t/visual" class="visual" mesh="gen_1_8_R_description/optimized/t" />
                        <geom name="R/t/collision" class="collision" mesh="gen_1_8_R_description/convex/t" />
                        <joint name="R/t0_TM_abd" axis="0 0 1" pos="0 0 0" range="0e+00 2.094395e+00" limited="true" />
                        <body name="R/meta_t_gen161" pos="-0.0000000 -0.0100000 0.0010000" quat="5e-01 -5e-01 5e-01 -5e-01">
                            <inertial mass="0.0657326" pos="0.0128147 0.0015230 0.0006213" diaginertia="6.943868e-06 6.560442e-06 7.766798e-06" />
                            <geom name="R/meta_t_gen161/visual" class="visual" mesh="gen_1_8_R_description/optimized/meta_t_gen161" />
                            <geom name="R/meta_t_gen161/collision" class="collision" mesh="gen_1_8_R_description/convex/meta_t_gen161" />
                            <joint name="R/t1_TM" axis="0 0 1" pos="0 0 0" range="-3.490658e-01 1.047198e+00" limited="true" />
                            <body name="R/prox_t_gen161" pos="0.0250000 0.0000000 -0.0000000" quat="7.010574e-01 9.229596e-02 9.229596e-02 -7.010574e-01">
                                <inertial mass="0.0399139" pos="0.0001981 0.0165019 0.0001321" diaginertia="4.471779e-06 2.049638e-06 4.560039e-06" />
                                <geom name="R/prox_t_gen161/visual" class="visual" mesh="gen_1_8_R_description/optimized/prox_t_gen161" />
                                <geom name="R/prox_t_gen161/collision" class="collision" mesh="gen_1_8_R_description/convex/prox_t_gen161" />
                                <joint name="R/t2_CMC" axis="0 0 1" pos="0 0 0" range="-3.490658e-01 1.570796e+00" limited="true" />
                                <body name="R/dist_t_gen161" pos="0.0000000 0.0320000 0.0000000" quat="1e+00 2.89313e-15 1.48492e-15 1.495e-17">
                                    <inertial mass="0.0469449" pos="-0.0012187 0.0158772 -0.0000500" diaginertia="4.630198e-06 1.888133e-06 4.643791e-06" />
                                    <geom name="R/dist_t_gen161/visual" class="visual" mesh="gen_1_8_R_description/optimized/dist_t_gen161" />
                                    <geom name="R/dist_t_gen161/collision" class="collision" mesh="gen_1_8_R_description/convex/dist_t_gen161" />
                                    <joint name="R/t3_DIP" axis="0 0 1" pos="0 0 0" range="-3.490658e-01 1.570796e+00" limited="true" />
                                </body>
                            </body>
                        </body>
                    </body>
                    <body name="R/sim1_f_gen1801_meta_gen181" pos="-0.0010000 0.1080000 0.0100000" quat="-7.071068e-01 -1.4943e-16 7.071068e-01 -4.7593e-16">
                        <inertial mass="0.0107395" pos="-0.0000014 0.0028816 -0.0003086" diaginertia="3.780428e-07 3.721189e-07 3.020315e-07" />
                        <geom name="R/sim1_f_gen1801_meta_gen181/visual" class="visual" mesh="gen_1_8_R_description/optimized/sim1_f_gen1801_meta_gen181" />
                        <geom name="R/sim1_f_gen1801_meta_gen181/collision" class="collision" mesh="gen_1_8_R_description/convex/sim1_f_gen1801_meta_gen181" />
                        <joint name="R/m0_CMC_abd" axis="0 0 1" pos="0 0 0" range="-2.617994e-01 2.617994e-01" limited="true" />
                        <body name="R/sim1_f_gen1801_prox_gen181" pos="0.0000000 0.0070000 -0.0000120" quat="0e+00 7.071068e-01 0e+00 7.071068e-01">
                            <inertial mass="0.0531353" pos="0.0027207 -0.0228719 0.0000000" diaginertia="7.274961e-06 2.192604e-06 6.663851e-06" />
                            <geom name="R/sim1_f_gen1801_prox_gen181/visual" class="visual" mesh="gen_1_8_R_description/optimized/sim1_f_gen1801_prox_gen181" />
                            <geom name="R/sim1_f_gen1801_prox_gen181/collision" class="collision" mesh="gen_1_8_R_description/convex/sim1_f_gen1801_prox_gen181" />
                            <joint name="R/m1_MCP" axis="0 0 1" pos="0 0 0" range="-3.490658e-01 1.570796e+00" limited="true" />
                            <body name="R/sim1_f_gen1801_med_gen181" pos="-0.0000000 -0.0420000 -0.0000000" quat="1e+00 -1.744e-17 0e+00 -4.597e-17">
                                <inertial mass="0.0235649" pos="0.0012835 -0.0130121 0.0000000" diaginertia="1.461732e-06 7.296005e-07 1.214972e-06" />
                                <geom name="R/sim1_f_gen1801_med_gen181/visual" class="visual" mesh="gen_1_8_R_description/optimized/sim1_f_gen1801_med_gen181" />
                                <geom name="R/sim1_f_gen1801_med_gen181/collision" class="collision" mesh="gen_1_8_R_description/convex/sim1_f_gen1801_med_gen181" />
                                <joint name="R/m2_PIP" axis="0 0 1" pos="0 0 0" range="-3.490658e-01 1.570796e+00" limited="true" />
                                <body name="R/sim1_f_gen1801_dist_gen181" pos="0.0040000 -0.0200000 -0.0000000" quat="1e+00 3.4056e-16 -2.7756e-16 -8.587e-17">
                                    <inertial mass="0.0294935" pos="-0.0020998 -0.0143962 -0.0000000" diaginertia="1.978919e-06 8.210773e-07 1.822869e-06" />
                                    <geom name="R/sim1_f_gen1801_dist_gen181/visual" class="visual" mesh="gen_1_8_R_description/optimized/sim1_f_gen1801_dist_gen181" />
                                    <geom name="R/sim1_f_gen1801_dist_gen181/collision" class="collision" mesh="gen_1_8_R_description/convex/sim1_f_gen1801_dist_gen181" />
                                    <joint name="R/m3_DIP" axis="0 0 1" pos="0 0 0" range="0e+00 1.570796e+00" limited="true" />
                                </body>
                            </body>
                        </body>
                    </body>
                    <body name="R/sim2_f_gen1801_meta_gen181" pos="-0.0010000 0.0980000 0.0310000" quat="-7.071068e-01 -1.4943e-16 7.071068e-01 -4.7593e-16">
                        <inertial mass="0.0107395" pos="-0.0000014 0.0028816 -0.0003086" diaginertia="3.780428e-07 3.721189e-07 3.020315e-07" />
                        <geom name="R/sim2_f_gen1801_meta_gen181/visual" class="visual" mesh="gen_1_8_R_description/optimized/sim2_f_gen1801_meta_gen181" />
                        <geom name="R/sim2_f_gen1801_meta_gen181/collision" class="collision" mesh="gen_1_8_R_description/convex/sim2_f_gen1801_meta_gen181" />
                        <joint name="R/i0_CMC_abd" axis="0 0 1" pos="0 0 0" range="-2.617994e-01 6.108652e-01" limited="true" />
                        <body name="R/sim2_f_gen1801_prox_gen181" pos="0.0000000 0.0070000 -0.0000120" quat="0e+00 7.071068e-01 0e+00 7.071068e-01">
                            <inertial mass="0.0531353" pos="0.0027207 -0.0228719 0.0000000" diaginertia="7.274961e-06 2.192604e-06 6.663851e-06" />
                            <geom name="R/sim2_f_gen1801_prox_gen181/visual" class="visual" mesh="gen_1_8_R_description/optimized/sim2_f_gen1801_prox_gen181" />
                            <geom name="R/sim2_f_gen1801_prox_gen181/collision" class="collision" mesh="gen_1_8_R_description/convex/sim2_f_gen1801_prox_gen181" />
                            <joint name="R/i1_MCP" axis="0 0 1" pos="0 0 0" range="-3.490658e-01 1.570796e+00" limited="true" />
                            <body name="R/sim2_f_gen1801_med_gen181" pos="-0.0000000 -0.0420000 -0.0000000" quat="1e+00 -1.744e-17 0e+00 -4.597e-17">
                                <inertial mass="0.0235649" pos="0.0012835 -0.0130121 0.0000000" diaginertia="1.461732e-06 7.296005e-07 1.214972e-06" />
                                <geom name="R/sim2_f_gen1801_med_gen181/visual" class="visual" mesh="gen_1_8_R_description/optimized/sim2_f_gen1801_med_gen181" />
                                <geom name="R/sim2_f_gen1801_med_gen181/collision" class="collision" mesh="gen_1_8_R_description/convex/sim2_f_gen1801_med_gen181" />
                                <joint name="R/i2_PIP" axis="0 0 1" pos="0 0 0" range="-3.490658e-01 1.570796e+00" limited="true" />
                                <body name="R/sim2_f_gen1801_dist_gen181" pos="0.0040000 -0.0200000 -0.0000000" quat="1e+00 3.4056e-16 -2.7756e-16 -8.587e-17">
                                    <inertial mass="0.0294935" pos="-0.0020998 -0.0143962 -0.0000000" diaginertia="1.978919e-06 8.210773e-07 1.822869e-06" />
                                    <geom name="R/sim2_f_gen1801_dist_gen181/visual" class="visual" mesh="gen_1_8_R_description/optimized/sim2_f_gen1801_dist_gen181" />
                                    <geom name="R/sim2_f_gen1801_dist_gen181/collision" class="collision" mesh="gen_1_8_R_description/convex/sim2_f_gen1801_dist_gen181" />
                                    <joint name="R/i3_DIP" axis="0 0 1" pos="0 0 0" range="0e+00 1.570796e+00" limited="true" />
                                </body>
                            </body>
                        </body>
                    </body>
                    <body name="R/sim3_f_gen1801_meta_gen181" pos="-0.0010000 0.0980000 -0.0110000" quat="-7.071068e-01 -1.4943e-16 7.071068e-01 -4.7593e-16">
                        <inertial mass="0.0107395" pos="-0.0000014 0.0028816 -0.0003086" diaginertia="3.780428e-07 3.721189e-07 3.020315e-07" />
                        <geom name="R/sim3_f_gen1801_meta_gen181/visual" class="visual" mesh="gen_1_8_R_description/optimized/sim3_f_gen1801_meta_gen181" />
                        <geom name="R/sim3_f_gen1801_meta_gen181/collision" class="collision" mesh="gen_1_8_R_description/convex/sim3_f_gen1801_meta_gen181" />
                        <joint name="R/r0_CMC_abd" axis="0 0 1" pos="0 0 0" range="-2.617994e-01 2.617994e-01" limited="true" />
                        <body name="R/sim3_f_gen1801_prox_gen181" pos="0.0000000 0.0070000 -0.0000120" quat="0e+00 7.071068e-01 0e+00 7.071068e-01">
                            <inertial mass="0.0531353" pos="0.0027207 -0.0228719 0.0000000" diaginertia="7.274961e-06 2.192604e-06 6.663851e-06" />
                            <geom name="R/sim3_f_gen1801_prox_gen181/visual" class="visual" mesh="gen_1_8_R_description/optimized/sim3_f_gen1801_prox_gen181" />
                            <geom name="R/sim3_f_gen1801_prox_gen181/collision" class="collision" mesh="gen_1_8_R_description/convex/sim3_f_gen1801_prox_gen181" />
                            <joint name="R/r1_MCP" axis="0 0 1" pos="0 0 0" range="-3.490658e-01 1.570796e+00" limited="true" />
                            <body name="R/sim3_f_gen1801_med_gen181" pos="-0.0000000 -0.0420000 -0.0000000" quat="1e+00 -1.744e-17 0e+00 -4.597e-17">
                                <inertial mass="0.0235649" pos="0.0012835 -0.0130121 0.0000000" diaginertia="1.461732e-06 7.296005e-07 1.214972e-06" />
                                <geom name="R/sim3_f_gen1801_med_gen181/visual" class="visual" mesh="gen_1_8_R_description/optimized/sim3_f_gen1801_med_gen181" />
                                <geom name="R/sim3_f_gen1801_med_gen181/collision" class="collision" mesh="gen_1_8_R_description/convex/sim3_f_gen1801_med_gen181" />
                                <joint name="R/r2_PIP" axis="0 0 1" pos="0 0 0" range="-3.490658e-01 1.570796e+00" limited="true" />
                                <body name="R/sim3_f_gen1801_dist_gen181" pos="0.0040000 -0.0200000 -0.0000000" quat="1e+00 3.4056e-16 -2.7756e-16 -8.587e-17">
                                    <inertial mass="0.0294935" pos="-0.0020998 -0.0143962 -0.0000000" diaginertia="1.978919e-06 8.210773e-07 1.822869e-06" />
                                    <geom name="R/sim3_f_gen1801_dist_gen181/visual" class="visual" mesh="gen_1_8_R_description/optimized/sim3_f_gen1801_dist_gen181" />
                                    <geom name="R/sim3_f_gen1801_dist_gen181/collision" class="collision" mesh="gen_1_8_R_description/convex/sim3_f_gen1801_dist_gen181" />
                                    <joint name="R/r3_DIP" axis="0 0 1" pos="0 0 0" range="0e+00 1.570796e+00" limited="true" />
                                </body>
                            </body>
                        </body>
                    </body>
                </body>
            </body>
        </body>
    </body>
</mujocoinclude>