<?xml version='1.0' encoding='utf-8'?>
<mujoco model="ProHand_V17">
    <!--
        ====================================================================================
        |                               Generation Metadata                                |
        ====================================================================================
        | Field           | Value                                                          |
        ====================================================================================
        | Generated on    | 2025-07-24 13:11:40 UTC                                        |
        | Repository      | fusion-to-sim-models                                           |
        | Remote URL      | git@github.com.jack:Proception-AI/fusion-to-sim-models         |
        | Branch          | user/jack/feature/keypoints_extraction                         |
        | Commit          | 83e01d9f44d4                                                   |
        | Generated by    | jack-proception                                                |
        | Generator       | fusion_to_sim_model                                            |
        | Generator class | YamlRobot                                                      |
        | Description     | (Post-processing based on YAML Robot Description Files [YRDF]) |
        ====================================================================================
    -->
    <compiler coordinate="local" angle="radian" meshdir="../meshes" />
    <visual>
        <scale framewidth="0.02" jointwidth="0.04" framelength="0.5" connect="0.1" />
    </visual>
    <default>
        <default class="visual">
            <geom type="mesh" contype="0" conaffinity="0" group="2" />
        </default>
        <default class="collision">
            <geom type="mesh" group="3" rgba="0.6 0.3 0.3 0.3" />
        </default>
        <default class="site/keypoint">
            <site rgba="1 0.2 0.2 0.8" size="0.002" group="0" />
        </default>
    </default>
    <asset>
        <mesh name="optimized/left_forearm1" file="optimized/left_forearm1.obj" />
        <mesh name="optimized/left_hand_wrist1_asy_prohand_v17_wrist_base_link1" file="optimized/left_hand_wrist1_asy_prohand_v17_wrist_base_link1.obj" />
        <mesh name="optimized/left_hand_wrist1_asy_prohand_v17_wrist_yaw_body1" file="optimized/left_hand_wrist1_asy_prohand_v17_wrist_yaw_body1.obj" />
        <mesh name="optimized/left_hand1_asy_prohand_v17_palm_base1" file="optimized/left_hand1_asy_prohand_v17_palm_base1.obj" />
        <mesh name="optimized/left_hand1_asy_prohand_v17_pinky1_hand_proximal_body1" file="optimized/left_hand1_asy_prohand_v17_pinky1_hand_proximal_body1.obj" />
        <mesh name="optimized/left_hand1_asy_prohand_v17_pinky1_hand_middle_body1" file="optimized/left_hand1_asy_prohand_v17_pinky1_hand_middle_body1.obj" />
        <mesh name="optimized/left_hand1_asy_prohand_v17_pinky1_hand_distal_body1" file="optimized/left_hand1_asy_prohand_v17_pinky1_hand_distal_body1.obj" />
        <mesh name="optimized/left_hand1_asy_prohand_v17_pinky1_hand_metacarpal_base_link1" file="optimized/left_hand1_asy_prohand_v17_pinky1_hand_metacarpal_base_link1.obj" />
        <mesh name="optimized/left_hand1_asy_prohand_v17_middle1_hand_finger2_proximal_body1" file="optimized/left_hand1_asy_prohand_v17_middle1_hand_finger2_proximal_body1.obj" />
        <mesh name="optimized/left_hand1_asy_prohand_v17_middle1_hand_finger2_middle_body1" file="optimized/left_hand1_asy_prohand_v17_middle1_hand_finger2_middle_body1.obj" />
        <mesh name="optimized/left_hand1_asy_prohand_v17_middle1_hand_finger2_distal_body1" file="optimized/left_hand1_asy_prohand_v17_middle1_hand_finger2_distal_body1.obj" />
        <mesh name="optimized/left_hand1_asy_prohand_v17_middle1_hand_finger2_metacarpal_base_link1" file="optimized/left_hand1_asy_prohand_v17_middle1_hand_finger2_metacarpal_base_link1.obj" />
        <mesh name="optimized/left_hand1_asy_prohand_v17_ring1_hand_finger3_proximal_body1" file="optimized/left_hand1_asy_prohand_v17_ring1_hand_finger3_proximal_body1.obj" />
        <mesh name="optimized/left_hand1_asy_prohand_v17_ring1_hand_finger3_middle_body1" file="optimized/left_hand1_asy_prohand_v17_ring1_hand_finger3_middle_body1.obj" />
        <mesh name="optimized/left_hand1_asy_prohand_v17_ring1_hand_finger3_distal_body1" file="optimized/left_hand1_asy_prohand_v17_ring1_hand_finger3_distal_body1.obj" />
        <mesh name="optimized/left_hand1_asy_prohand_v17_ring1_hand_finger3_metacarpal_base_link1" file="optimized/left_hand1_asy_prohand_v17_ring1_hand_finger3_metacarpal_base_link1.obj" />
        <mesh name="optimized/left_hand1_asy_prohand_v17_index1_hand_finger1_proximal_body1" file="optimized/left_hand1_asy_prohand_v17_index1_hand_finger1_proximal_body1.obj" />
        <mesh name="optimized/left_hand1_asy_prohand_v17_index1_hand_finger1_middle_body1" file="optimized/left_hand1_asy_prohand_v17_index1_hand_finger1_middle_body1.obj" />
        <mesh name="optimized/left_hand1_asy_prohand_v17_index1_hand_finger1_distal_body1" file="optimized/left_hand1_asy_prohand_v17_index1_hand_finger1_distal_body1.obj" />
        <mesh name="optimized/left_hand1_asy_prohand_v17_index1_hand_finger1_metacarpal_base_link1" file="optimized/left_hand1_asy_prohand_v17_index1_hand_finger1_metacarpal_base_link1.obj" />
        <mesh name="optimized/left_hand1_asy_prohand_v17_thumb1_hand_trapezium_body_base_link1" file="optimized/left_hand1_asy_prohand_v17_thumb1_hand_trapezium_body_base_link1.obj" />
        <mesh name="optimized/left_hand1_asy_prohand_v17_thumb1_hand_metacarpal_body1" file="optimized/left_hand1_asy_prohand_v17_thumb1_hand_metacarpal_body1.obj" />
        <mesh name="optimized/left_hand1_asy_prohand_v17_thumb1_hand_proximal_body1" file="optimized/left_hand1_asy_prohand_v17_thumb1_hand_proximal_body1.obj" />
        <mesh name="optimized/left_hand1_asy_prohand_v17_thumb1_hand_distal_body1" file="optimized/left_hand1_asy_prohand_v17_thumb1_hand_distal_body1.obj" />
        <mesh name="convex/left_forearm1" file="convex/left_forearm1.obj" />
        <mesh name="convex/left_hand_wrist1_asy_prohand_v17_wrist_base_link1" file="convex/left_hand_wrist1_asy_prohand_v17_wrist_base_link1.obj" />
        <mesh name="convex/left_hand_wrist1_asy_prohand_v17_wrist_yaw_body1" file="convex/left_hand_wrist1_asy_prohand_v17_wrist_yaw_body1.obj" />
        <mesh name="convex/left_hand1_asy_prohand_v17_palm_base1" file="convex/left_hand1_asy_prohand_v17_palm_base1.obj" />
        <mesh name="convex/left_hand1_asy_prohand_v17_pinky1_hand_proximal_body1" file="convex/left_hand1_asy_prohand_v17_pinky1_hand_proximal_body1.obj" />
        <mesh name="convex/left_hand1_asy_prohand_v17_pinky1_hand_middle_body1" file="convex/left_hand1_asy_prohand_v17_pinky1_hand_middle_body1.obj" />
        <mesh name="convex/left_hand1_asy_prohand_v17_pinky1_hand_distal_body1" file="convex/left_hand1_asy_prohand_v17_pinky1_hand_distal_body1.obj" />
        <mesh name="convex/left_hand1_asy_prohand_v17_pinky1_hand_metacarpal_base_link1" file="convex/left_hand1_asy_prohand_v17_pinky1_hand_metacarpal_base_link1.obj" />
        <mesh name="convex/left_hand1_asy_prohand_v17_middle1_hand_finger2_proximal_body1" file="convex/left_hand1_asy_prohand_v17_middle1_hand_finger2_proximal_body1.obj" />
        <mesh name="convex/left_hand1_asy_prohand_v17_middle1_hand_finger2_middle_body1" file="convex/left_hand1_asy_prohand_v17_middle1_hand_finger2_middle_body1.obj" />
        <mesh name="convex/left_hand1_asy_prohand_v17_middle1_hand_finger2_distal_body1" file="convex/left_hand1_asy_prohand_v17_middle1_hand_finger2_distal_body1.obj" />
        <mesh name="convex/left_hand1_asy_prohand_v17_middle1_hand_finger2_metacarpal_base_link1" file="convex/left_hand1_asy_prohand_v17_middle1_hand_finger2_metacarpal_base_link1.obj" />
        <mesh name="convex/left_hand1_asy_prohand_v17_ring1_hand_finger3_proximal_body1" file="convex/left_hand1_asy_prohand_v17_ring1_hand_finger3_proximal_body1.obj" />
        <mesh name="convex/left_hand1_asy_prohand_v17_ring1_hand_finger3_middle_body1" file="convex/left_hand1_asy_prohand_v17_ring1_hand_finger3_middle_body1.obj" />
        <mesh name="convex/left_hand1_asy_prohand_v17_ring1_hand_finger3_distal_body1" file="convex/left_hand1_asy_prohand_v17_ring1_hand_finger3_distal_body1.obj" />
        <mesh name="convex/left_hand1_asy_prohand_v17_ring1_hand_finger3_metacarpal_base_link1" file="convex/left_hand1_asy_prohand_v17_ring1_hand_finger3_metacarpal_base_link1.obj" />
        <mesh name="convex/left_hand1_asy_prohand_v17_index1_hand_finger1_proximal_body1" file="convex/left_hand1_asy_prohand_v17_index1_hand_finger1_proximal_body1.obj" />
        <mesh name="convex/left_hand1_asy_prohand_v17_index1_hand_finger1_middle_body1" file="convex/left_hand1_asy_prohand_v17_index1_hand_finger1_middle_body1.obj" />
        <mesh name="convex/left_hand1_asy_prohand_v17_index1_hand_finger1_distal_body1" file="convex/left_hand1_asy_prohand_v17_index1_hand_finger1_distal_body1.obj" />
        <mesh name="convex/left_hand1_asy_prohand_v17_index1_hand_finger1_metacarpal_base_link1" file="convex/left_hand1_asy_prohand_v17_index1_hand_finger1_metacarpal_base_link1.obj" />
        <mesh name="convex/left_hand1_asy_prohand_v17_thumb1_hand_trapezium_body_base_link1" file="convex/left_hand1_asy_prohand_v17_thumb1_hand_trapezium_body_base_link1.obj" />
        <mesh name="convex/left_hand1_asy_prohand_v17_thumb1_hand_metacarpal_body1" file="convex/left_hand1_asy_prohand_v17_thumb1_hand_metacarpal_body1.obj" />
        <mesh name="convex/left_hand1_asy_prohand_v17_thumb1_hand_proximal_body1" file="convex/left_hand1_asy_prohand_v17_thumb1_hand_proximal_body1.obj" />
        <mesh name="convex/left_hand1_asy_prohand_v17_thumb1_hand_distal_body1" file="convex/left_hand1_asy_prohand_v17_thumb1_hand_distal_body1.obj" />
    </asset>
    <worldbody>
        <body name="FOREARM1" pos="0.0000000 0.0000000 0.0000000" quat="1e+00 0e+00 0e+00 0e+00">
            <inertial mass="3.9427676" pos="-0.0043528 -0.0000449 0.1073299" diaginertia="1.526145e-02 1.522456e-02 4.313841e-03" />
            <geom name="FOREARM1/visual" class="visual" mesh="optimized/left_forearm1" />
            <geom name="FOREARM1/collision/capsule" class="collision" type="capsule" size="0.059358020920385536 0.08186706404052914" pos="0.000424 0.000002 0.113960" quat="0.999992 0.000007 -0.003923 0.000000" />
            <!--Primitive collision: CapsulePrimitive - radius=0.0594, length=0.1637-->
            <body name="wrist1/wrist_base_(base_link)1" pos="-0.0050000 0.0000000 0.2203000" quat="1e+00 0e+00 0e+00 0e+00">
                <inertial mass="0.0598453" pos="0.0000027 0.0000166 0.0074329" diaginertia="7.91751e-06 1.003025e-05 1.142026e-05" />
                <geom name="wrist1/wrist_base_(base_link)1/visual" class="visual" mesh="optimized/left_hand_wrist1_asy_prohand_v17_wrist_base_link1" />
                <geom name="wrist1/wrist_base_(base_link)1/collision/capsule" class="collision" type="capsule" size="0.02247176607966976 0.0008717383247208185" pos="-0.000197 0.000027 0.010167" quat="0.765809 0.261645 0.587434 -0.000000" />
                <!--Primitive collision: CapsulePrimitive - radius=0.0225, length=0.0017-->
                <body name="Body1" pos="0.0000000 -0.0000000 0.0200000" quat="0e+00 7.071068e-01 0e+00 7.071068e-01">
                    <inertial mass="0.0893144" pos="0.0102605 0.0000213 0.0030975" diaginertia="2.136406e-05 1.967471e-05 2.998291e-05" />
                    <geom name="Body1/visual" class="visual" mesh="optimized/left_hand_wrist1_asy_prohand_v17_wrist_yaw_body1" />
                    <geom name="Body1/collision/box" class="collision" type="box" size="0.018141 0.032555 0.032476" pos="0.009038 -0.001106 0.003796" quat="1.000000 0.000000 0.000000 0.000000" />
                    <!--Primitive collision: BoxPrimitive - dimensions=[0.0363, 0.0651, 0.0650]-->
                    <joint name="yaw" axis="0 0 1" pos="0 0 0" range="-5.235988e-01 5.235988e-01" limited="true" />
                    <body name="base1" pos="0.0180000 -0.0000000 0.0050000" quat="5e-01 5e-01 -5e-01 5e-01">
                        <inertial mass="0.2154247" pos="-0.0007858 -0.0504603 0.0009974" diaginertia="2.888739e-04 1.128874e-04 2.004196e-04" />
                        <geom name="base1/visual" class="visual" mesh="optimized/left_hand1_asy_prohand_v17_palm_base1" />
                        <geom name="base1/collision" class="collision" mesh="convex/left_hand1_asy_prohand_v17_palm_base1" />
                        <joint name="pitch" axis="0 0 1" pos="0 0 0" range="-5.235988e-01 1.047198e+00" limited="true" />
                        <body name="Finger1/metacarpal_base_(base_link)1" pos="0.0010000 -0.0980000 -0.0310000" quat="5.888e-17 7.071068e-01 6.4779e-16 7.071068e-01">
                            <inertial mass="0.0044634" pos="-0.0000002 0.0037355 -0.0003225" diaginertia="1.474219e-07 1.333687e-07 1.205535e-07" />
                            <geom name="Finger1/metacarpal_base_(base_link)1/visual" class="visual" mesh="optimized/left_hand1_asy_prohand_v17_index1_hand_finger1_metacarpal_base_link1" />
                            <geom name="Finger1/metacarpal_base_(base_link)1/collision/capsule" class="collision" type="capsule" size="0.009275237950033051 0.005976383148152113" pos="0.000000 0.001856 0.000995" quat="0.274466 -0.961597 -0.000047 0.000000" />
                            <!--Primitive collision: CapsulePrimitive - radius=0.0093, length=0.0120-->
                            <joint name="Hand1/i0_CMC_abd" axis="0 0 1" pos="0 0 0" range="-2.617994e-01 5.235988e-01" limited="true" />
                            <body name="Finger1/proximal_body1" pos="-0.0000000 0.0070000 -0.0000120" quat="0e+00 7.071068e-01 0e+00 7.071068e-01">
                                <inertial mass="0.0122797" pos="0.0026042 -0.0218771 0.0000000" diaginertia="1.907123e-06 4.327426e-07 1.788289e-06" />
                                <geom name="Finger1/proximal_body1/visual" class="visual" mesh="optimized/left_hand1_asy_prohand_v17_index1_hand_finger1_proximal_body1" />
                                <geom name="Finger1/proximal_body1/collision/capsule" class="collision" type="capsule" size="0.010431328506267396 0.02264878108237772" pos="0.002309 -0.020956 0.000216" quat="0.711329 0.702817 -0.007705 0.000000" />
                                <!--Primitive collision: CapsulePrimitive - radius=0.0104, length=0.0453-->
                                <joint name="Finger1/j1_MCP" axis="0 0 1" pos="0 0 0" range="-3.490658e-01 1.570796e+00" limited="true" />
                                <body name="Finger1/middle_body1" pos="0.0000000 -0.0420000 0.0000000" quat="1e+00 0e+00 0e+00 5.551e-17">
                                    <inertial mass="0.0050835" pos="0.0018313 -0.0112756 -0.0000000" diaginertia="3.539997e-07 1.518711e-07 3.039656e-07" />
                                    <geom name="Finger1/middle_body1/visual" class="visual" mesh="optimized/left_hand1_asy_prohand_v17_index1_hand_finger1_middle_body1" />
                                    <geom name="Finger1/middle_body1/collision/capsule" class="collision" type="capsule" size="0.008684273736263425 0.009736844043130088" pos="0.001887 -0.010038 0.000000" quat="0.707173 -0.706229 -0.033850 0.000000" />
                                    <!--Primitive collision: CapsulePrimitive - radius=0.0087, length=0.0195-->
                                    <joint name="Finger1/j2_PIP" axis="0 0 1" pos="0 0 0" range="-2.617994e-01 1.570796e+00" limited="true" />
                                    <body name="Finger1/distal_body1" pos="0.0040000 -0.0200000 0.0000000" quat="1e+00 -0e+00 0e+00 -0e+00">
                                        <inertial mass="0.0064517" pos="-0.0021032 -0.0123773 -0.0000000" diaginertia="4.615383e-07 1.770777e-07 4.245303e-07" />
                                        <geom name="Finger1/distal_body1/visual" class="visual" mesh="optimized/left_hand1_asy_prohand_v17_index1_hand_finger1_distal_body1" />
                                        <geom name="Finger1/distal_body1/collision/capsule" class="collision" type="capsule" size="0.009047332363629826 0.009146820081954514" pos="-0.002378 -0.011098 0.000008" quat="0.708229 0.703020 -0.064607 0.000000" />
                                        <!--Primitive collision: CapsulePrimitive - radius=0.0090, length=0.0183-->
                                        <joint name="Finger1/j3_DIP" axis="0 0 1" pos="0 0 0" range="0e+00 1.570796e+00" limited="true" />
                                    </body>
                                </body>
                            </body>
                        </body>
                        <body name="Finger2/metacarpal_base_(base_link)1" pos="0.0010000 -0.1080000 -0.0100000" quat="5.888e-17 7.071068e-01 6.4779e-16 7.071068e-01">
                            <inertial mass="0.0044634" pos="-0.0000002 0.0037355 -0.0003225" diaginertia="1.474219e-07 1.333687e-07 1.205535e-07" />
                            <geom name="Finger2/metacarpal_base_(base_link)1/visual" class="visual" mesh="optimized/left_hand1_asy_prohand_v17_middle1_hand_finger2_metacarpal_base_link1" />
                            <geom name="Finger2/metacarpal_base_(base_link)1/collision/capsule" class="collision" type="capsule" size="0.009275237950033051 0.005976383148152113" pos="0.000000 0.001856 0.000995" quat="0.274466 -0.961597 -0.000047 0.000000" />
                            <!--Primitive collision: CapsulePrimitive - radius=0.0093, length=0.0120-->
                            <joint name="Hand1/m0_CMC_abd" axis="0 0 1" pos="0 0 0" range="-2.617994e-01 2.617994e-01" limited="true" />
                            <body name="Finger2/proximal_body1" pos="-0.0000000 0.0070000 -0.0000120" quat="0e+00 7.071068e-01 0e+00 7.071068e-01">
                                <inertial mass="0.0122797" pos="0.0026042 -0.0218771 0.0000000" diaginertia="1.907123e-06 4.327426e-07 1.788289e-06" />
                                <geom name="Finger2/proximal_body1/visual" class="visual" mesh="optimized/left_hand1_asy_prohand_v17_middle1_hand_finger2_proximal_body1" />
                                <geom name="Finger2/proximal_body1/collision/capsule" class="collision" type="capsule" size="0.010431328506267396 0.02264878108237772" pos="0.002309 -0.020956 0.000216" quat="0.711329 0.702817 -0.007705 0.000000" />
                                <!--Primitive collision: CapsulePrimitive - radius=0.0104, length=0.0453-->
                                <joint name="Finger2/j1_MCP" axis="0 0 1" pos="0 0 0" range="-3.490658e-01 1.570796e+00" limited="true" />
                                <body name="Finger2/middle_body1" pos="0.0000000 -0.0420000 0.0000000" quat="1e+00 0e+00 0e+00 5.551e-17">
                                    <inertial mass="0.0050835" pos="0.0018313 -0.0112756 -0.0000000" diaginertia="3.539997e-07 1.518711e-07 3.039656e-07" />
                                    <geom name="Finger2/middle_body1/visual" class="visual" mesh="optimized/left_hand1_asy_prohand_v17_middle1_hand_finger2_middle_body1" />
                                    <geom name="Finger2/middle_body1/collision/capsule" class="collision" type="capsule" size="0.008684273736263425 0.009736844043130088" pos="0.001887 -0.010038 0.000000" quat="0.707173 -0.706229 -0.033850 0.000000" />
                                    <!--Primitive collision: CapsulePrimitive - radius=0.0087, length=0.0195-->
                                    <joint name="Finger2/j2_PIP" axis="0 0 1" pos="0 0 0" range="-2.617994e-01 1.570796e+00" limited="true" />
                                    <body name="Finger2/distal_body1" pos="0.0040000 -0.0200000 0.0000000" quat="1e+00 -0e+00 0e+00 -0e+00">
                                        <inertial mass="0.0064517" pos="-0.0021032 -0.0123773 -0.0000000" diaginertia="4.615383e-07 1.770777e-07 4.245303e-07" />
                                        <geom name="Finger2/distal_body1/visual" class="visual" mesh="optimized/left_hand1_asy_prohand_v17_middle1_hand_finger2_distal_body1" />
                                        <geom name="Finger2/distal_body1/collision/capsule" class="collision" type="capsule" size="0.009047332363629826 0.009146820081954514" pos="-0.002378 -0.011098 0.000008" quat="0.708229 0.703020 -0.064607 0.000000" />
                                        <!--Primitive collision: CapsulePrimitive - radius=0.0090, length=0.0183-->
                                        <joint name="Finger2/j3_DIP" axis="0 0 1" pos="0 0 0" range="0e+00 1.570796e+00" limited="true" />
                                    </body>
                                </body>
                            </body>
                        </body>
                        <body name="Pinky1/metacarpal_base_(base_link)1" pos="0.0010000 -0.0930000 0.0320000" quat="5.888e-17 7.071068e-01 6.4779e-16 7.071068e-01">
                            <inertial mass="0.0044634" pos="-0.0000002 0.0037355 -0.0003225" diaginertia="1.474219e-07 1.333687e-07 1.205535e-07" />
                            <geom name="Pinky1/metacarpal_base_(base_link)1/visual" class="visual" mesh="optimized/left_hand1_asy_prohand_v17_pinky1_hand_metacarpal_base_link1" />
                            <geom name="Pinky1/metacarpal_base_(base_link)1/collision/capsule" class="collision" type="capsule" size="0.00927753366832892 0.005968686465202594" pos="-0.000000 0.001857 0.000995" quat="0.961587 0.274499 0.000000 -0.000000" />
                            <!--Primitive collision: CapsulePrimitive - radius=0.0093, length=0.0119-->
                            <joint name="Hand1/p0_CMC_abd" axis="0 0 1" pos="0 0 0" range="-6.108652e-01 2.617994e-01" limited="true" />
                            <body name="Pinky1/proximal_body1" pos="0.0000000 0.0070000 -0.0000120" quat="0e+00 7.071068e-01 0e+00 7.071068e-01">
                                <inertial mass="0.0210231" pos="0.0030714 -0.0174744 -0.0000006" diaginertia="1.47529e-06 9.286679e-07 1.244961e-06" />
                                <geom name="Pinky1/proximal_body1/visual" class="visual" mesh="optimized/left_hand1_asy_prohand_v17_pinky1_hand_proximal_body1" />
                                <geom name="Pinky1/proximal_body1/collision/capsule" class="collision" type="capsule" size="0.010332594455389053 0.012489160115579654" pos="0.002799 -0.013472 0.000001" quat="0.707120 0.706531 0.028197 -0.000000" />
                                <!--Primitive collision: CapsulePrimitive - radius=0.0103, length=0.0250-->
                                <joint name="Pinky1/j1_MCP" axis="0 0 1" pos="0 0 0" range="-3.490658e-01 1.570796e+00" limited="true" />
                                <body name="Pinky1/middle_body1" pos="0.0000000 -0.0320000 -0.0000000" quat="1e+00 1.3796e-16 -1.1102e-16 -4e-20">
                                    <inertial mass="0.0050835" pos="0.0018313 -0.0112756 -0.0000000" diaginertia="3.539997e-07 1.518711e-07 3.039656e-07" />
                                    <geom name="Pinky1/middle_body1/visual" class="visual" mesh="optimized/left_hand1_asy_prohand_v17_pinky1_hand_middle_body1" />
                                    <geom name="Pinky1/middle_body1/collision/capsule" class="collision" type="capsule" size="0.008684273865243848 0.009736844447603869" pos="0.001887 -0.010038 0.000000" quat="0.707173 -0.706229 -0.033850 0.000000" />
                                    <!--Primitive collision: CapsulePrimitive - radius=0.0087, length=0.0195-->
                                    <joint name="Pinky1/j2_PIP" axis="0 0 1" pos="0 0 0" range="-2.617994e-01 1.570796e+00" limited="true" />
                                    <body name="Pinky1/distal_body1" pos="0.0040000 -0.0200000 -0.0000000" quat="1e+00 2.963e-17 0e+00 -1.384e-17">
                                        <inertial mass="0.0059230" pos="-0.0016616 -0.0128501 0.0000005" diaginertia="4.257244e-07 1.446234e-07 4.098516e-07" />
                                        <geom name="Pinky1/distal_body1/visual" class="visual" mesh="optimized/left_hand1_asy_prohand_v17_pinky1_hand_distal_body1" />
                                        <geom name="Pinky1/distal_body1/collision/capsule" class="collision" type="capsule" size="0.008075143427988707 0.015160004548427678" pos="-0.001545 -0.010620 0.000001" quat="0.707637 0.706557 0.005181 -0.000000" />
                                        <!--Primitive collision: CapsulePrimitive - radius=0.0081, length=0.0303-->
                                        <joint name="Pinky1/j3_DIP" axis="0 0 1" pos="0 0 0" range="0e+00 1.570796e+00" limited="true" />
                                    </body>
                                </body>
                            </body>
                        </body>
                        <body name="Finger3/metacarpal_base_(base_link)1" pos="0.0010000 -0.0980000 0.0110000" quat="5.888e-17 7.071068e-01 6.4779e-16 7.071068e-01">
                            <inertial mass="0.0044634" pos="-0.0000002 0.0037355 -0.0003225" diaginertia="1.474219e-07 1.333687e-07 1.205535e-07" />
                            <geom name="Finger3/metacarpal_base_(base_link)1/visual" class="visual" mesh="optimized/left_hand1_asy_prohand_v17_ring1_hand_finger3_metacarpal_base_link1" />
                            <geom name="Finger3/metacarpal_base_(base_link)1/collision/capsule" class="collision" type="capsule" size="0.009275237950033051 0.005976383148152113" pos="0.000000 0.001856 0.000995" quat="0.274466 -0.961597 -0.000047 0.000000" />
                            <!--Primitive collision: CapsulePrimitive - radius=0.0093, length=0.0120-->
                            <joint name="Hand1/r0_CMC_abd" axis="0 0 1" pos="0 0 0" range="-2.617994e-01 2.617994e-01" limited="true" />
                            <body name="Finger3/proximal_body1" pos="-0.0000000 0.0070000 -0.0000120" quat="0e+00 7.071068e-01 0e+00 7.071068e-01">
                                <inertial mass="0.0122797" pos="0.0026042 -0.0218771 0.0000000" diaginertia="1.907123e-06 4.327426e-07 1.788289e-06" />
                                <geom name="Finger3/proximal_body1/visual" class="visual" mesh="optimized/left_hand1_asy_prohand_v17_ring1_hand_finger3_proximal_body1" />
                                <geom name="Finger3/proximal_body1/collision/capsule" class="collision" type="capsule" size="0.010431328506267396 0.02264878108237772" pos="0.002309 -0.020956 0.000216" quat="0.711329 0.702817 -0.007705 0.000000" />
                                <!--Primitive collision: CapsulePrimitive - radius=0.0104, length=0.0453-->
                                <joint name="Finger3/j1_MCP" axis="0 0 1" pos="0 0 0" range="-3.490658e-01 1.570796e+00" limited="true" />
                                <body name="Finger3/middle_body1" pos="0.0000000 -0.0420000 0.0000000" quat="1e+00 0e+00 0e+00 5.551e-17">
                                    <inertial mass="0.0050835" pos="0.0018313 -0.0112756 -0.0000000" diaginertia="3.539997e-07 1.518711e-07 3.039656e-07" />
                                    <geom name="Finger3/middle_body1/visual" class="visual" mesh="optimized/left_hand1_asy_prohand_v17_ring1_hand_finger3_middle_body1" />
                                    <geom name="Finger3/middle_body1/collision/capsule" class="collision" type="capsule" size="0.008684273736263425 0.009736844043130088" pos="0.001887 -0.010038 0.000000" quat="0.707173 -0.706229 -0.033850 0.000000" />
                                    <!--Primitive collision: CapsulePrimitive - radius=0.0087, length=0.0195-->
                                    <joint name="Finger3/j2_PIP" axis="0 0 1" pos="0 0 0" range="-2.617994e-01 1.570796e+00" limited="true" />
                                    <body name="Finger3/distal_body1" pos="0.0040000 -0.0200000 0.0000000" quat="1e+00 -0e+00 0e+00 -0e+00">
                                        <inertial mass="0.0064517" pos="-0.0021032 -0.0123773 -0.0000000" diaginertia="4.615383e-07 1.770777e-07 4.245303e-07" />
                                        <geom name="Finger3/distal_body1/visual" class="visual" mesh="optimized/left_hand1_asy_prohand_v17_ring1_hand_finger3_distal_body1" />
                                        <geom name="Finger3/distal_body1/collision/capsule" class="collision" type="capsule" size="0.009047332363629826 0.009146820081954514" pos="-0.002378 -0.011098 0.000008" quat="0.708229 0.703020 -0.064607 0.000000" />
                                        <!--Primitive collision: CapsulePrimitive - radius=0.0090, length=0.0183-->
                                        <joint name="Finger3/j3_DIP" axis="0 0 1" pos="0 0 0" range="0e+00 1.570796e+00" limited="true" />
                                    </body>
                                </body>
                            </body>
                        </body>
                        <body name="body_(base_link)1" pos="0.0100000 -0.0395289 -0.0235680" quat="8.19152e-01 5.735764e-01 6.2623e-16 -1.82161e-15">
                            <inertial mass="0.0073437" pos="-0.0005965 -0.0030255 0.0001268" diaginertia="4.082471e-07 5.791672e-07 4.940715e-07" />
                            <geom name="body_(base_link)1/visual" class="visual" mesh="optimized/left_hand1_asy_prohand_v17_thumb1_hand_trapezium_body_base_link1" />
                            <geom name="body_(base_link)1/collision/box" class="collision" type="box" size="0.010000 0.010979 0.012500" pos="-0.000000 -0.003979 0.001500" quat="1.000000 0.000000 0.000000 0.000000" />
                            <!--Primitive collision: BoxPrimitive - dimensions=[0.0200, 0.0220, 0.0250]-->
                            <joint name="TM_abd" axis="0 0 1" pos="0 0 0" range="0e+00 2.094395e+00" limited="true" />
                            <body name="Thumb1/metacarpal_body1" pos="-0.0000000 -0.0100000 -0.0010000" quat="7.071068e-01 9.625e-17 -7.071068e-01 6.538e-17">
                                <inertial mass="0.0149694" pos="0.0030358 -0.0110728 -0.0005006" diaginertia="1.661677e-06 1.238059e-06 1.518884e-06" />
                                <geom name="Thumb1/metacarpal_body1/visual" class="visual" mesh="optimized/left_hand1_asy_prohand_v17_thumb1_hand_metacarpal_body1" />
                                <geom name="Thumb1/metacarpal_body1/collision/capsule" class="collision" type="capsule" size="0.017183081577488414 0.005345586638421002" pos="0.003682 -0.010062 -0.000908" quat="0.681567 -0.711978 -0.168981 0.000000" />
                                <!--Primitive collision: CapsulePrimitive - radius=0.0172, length=0.0107-->
                                <joint name="TM" axis="0 0 1" pos="0 0 0" range="-5.235988e-01 1.047198e+00" limited="true" />
                                <body name="Thumb1/proximal_body1" pos="0.0043412 -0.0246202 -0.0000000" quat="-8.641011e-02 1.300295e-01 1.137611e-02 9.876721e-01">
                                    <inertial mass="0.0111003" pos="0.0000960 0.0148200 -0.0000732" diaginertia="1.420007e-06 4.048893e-07 1.331462e-06" />
                                    <geom name="Thumb1/proximal_body1/visual" class="visual" mesh="optimized/left_hand1_asy_prohand_v17_thumb1_hand_proximal_body1" />
                                    <geom name="Thumb1/proximal_body1/collision/capsule" class="collision" type="capsule" size="0.009721164193367614 0.01551682190095351" pos="-0.000371 0.018203 0.000005" quat="0.707265 -0.706929 0.005207 0.000000" />
                                    <!--Primitive collision: CapsulePrimitive - radius=0.0097, length=0.0310-->
                                    <joint name="Thumb1/t2_MCP" axis="0 0 1" pos="0 0 0" range="0e+00 1.308997e+00" limited="true" />
                                    <body name="Thumb1/distal_body1" pos="0.0000000 0.0320000 0.0000000" quat="1e+00 9.9573e-16 -8.8124e-16 -1.24206e-15">
                                        <inertial mass="0.0100941" pos="-0.0006335 0.0143295 -0.0000000" diaginertia="1.108719e-06 3.245735e-07 1.083928e-06" />
                                        <geom name="Thumb1/distal_body1/visual" class="visual" mesh="optimized/left_hand1_asy_prohand_v17_thumb1_hand_distal_body1" />
                                        <geom name="Thumb1/distal_body1/collision/capsule" class="collision" type="capsule" size="0.009573708397391141 0.011600651934709239" pos="-0.001397 0.014781 -0.000000" quat="0.707051 -0.707162 0.000967 0.000000" />
                                        <!--Primitive collision: CapsulePrimitive - radius=0.0096, length=0.0232-->
                                        <joint name="Thumb1/t3_DIP" axis="0 0 1" pos="0 0 0" range="0e+00 1.570796e+00" limited="true" />
                                    </body>
                                </body>
                            </body>
                        </body>
                    </body>
                </body>
            </body>
        </body>
    </worldbody>
</mujoco>