<?xml version='1.0' encoding='utf-8'?>
<mujoco model="ProHand_V18R">
    <!--
        ====================================================================================
        |                               Generation Metadata                                |
        ====================================================================================
        | Field           | Value                                                          |
        ====================================================================================
        | Generated on    | 2025-07-30 22:45:33 UTC                                        |
        | Repository      | fusion-to-sim-models                                           |
        | Remote URL      | git@github.com.jack:Proception-AI/fusion-to-sim-models         |
        | Branch          | user/jack/feature/keypoints_extraction                         |
        | Commit          | af5a017184cc                                                   |
        | Generated by    | jack-proception                                                |
        | Generator       | fusion_to_sim_model                                            |
        | Generator class | YamlRobot                                                      |
        | Description     | (Post-processing based on YAML Robot Description Files [YRDF]) |
        ====================================================================================
    -->
    <compiler coordinate="local" angle="radian" meshdir="../meshes" />
    <visual>
        <scale framewidth="0.02" jointwidth="0.04" framelength="0.5" connect="0.1" />
    </visual>
    <default>
        <default class="visual">
            <geom type="mesh" contype="0" conaffinity="0" group="2" />
        </default>
        <default class="collision">
            <geom type="mesh" group="3" rgba="0.6 0.3 0.3 0.3" />
        </default>
        <default class="site/keypoint">
            <site rgba="1 0.2 0.2 0.8" size="0.002" group="0" />
        </default>
    </default>
    <asset>
        <mesh name="optimized/right_forearm1" file="optimized/right_forearm1.obj" />
        <mesh name="optimized/prohand_v18r_hand1_asy_v18_handr1_rthumb_gen181_chassis_distal_thumb_gen161" file="optimized/prohand_v18r_hand1_asy_v18_handr1_rthumb_gen181_chassis_distal_thumb_gen161.obj" />
        <mesh name="optimized/prohand_v18r_hand1_asy_v18_handr1_rthumb_gen181_chassis_proximal_thumb_gen161" file="optimized/prohand_v18r_hand1_asy_v18_handr1_rthumb_gen181_chassis_proximal_thumb_gen161.obj" />
        <mesh name="optimized/prohand_v18r_hand1_asy_v18_handr1_rthumb_gen181_chassis_metacarpal_thumb_gen161" file="optimized/prohand_v18r_hand1_asy_v18_handr1_rthumb_gen181_chassis_metacarpal_thumb_gen161.obj" />
        <mesh name="optimized/prohand_v18r_hand1_asy_v18_handr1_rthumb_gen181_trapezium_thumb" file="optimized/prohand_v18r_hand1_asy_v18_handr1_rthumb_gen181_trapezium_thumb.obj" />
        <mesh name="optimized/prohand_v18r_hand1_asy_v18_handr1_rpalm_gen181_palm1" file="optimized/prohand_v18r_hand1_asy_v18_handr1_rpalm_gen181_palm1.obj" />
        <mesh name="optimized/prohand_v18r_hand1_asy_v18_handr1_onefinger_sim3_finger_gen1801_distal_gen181" file="optimized/prohand_v18r_hand1_asy_v18_handr1_onefinger_sim3_finger_gen1801_distal_gen181.obj" />
        <mesh name="optimized/prohand_v18r_hand1_asy_v18_handr1_onefinger_sim3_finger_gen1801_medial_gen181" file="optimized/prohand_v18r_hand1_asy_v18_handr1_onefinger_sim3_finger_gen1801_medial_gen181.obj" />
        <mesh name="optimized/prohand_v18r_hand1_asy_v18_handr1_onefinger_sim3_finger_gen1801_proximal_gen181" file="optimized/prohand_v18r_hand1_asy_v18_handr1_onefinger_sim3_finger_gen1801_proximal_gen181.obj" />
        <mesh name="optimized/prohand_v18r_hand1_asy_v18_handr1_onefinger_sim3_finger_gen1801_metacarpal_gen181" file="optimized/prohand_v18r_hand1_asy_v18_handr1_onefinger_sim3_finger_gen1801_metacarpal_gen181.obj" />
        <mesh name="optimized/prohand_v18r_hand1_asy_v18_handr1_onefinger_sim1_finger_gen1801_distal_gen181" file="optimized/prohand_v18r_hand1_asy_v18_handr1_onefinger_sim1_finger_gen1801_distal_gen181.obj" />
        <mesh name="optimized/prohand_v18r_hand1_asy_v18_handr1_onefinger_sim1_finger_gen1801_medial_gen181" file="optimized/prohand_v18r_hand1_asy_v18_handr1_onefinger_sim1_finger_gen1801_medial_gen181.obj" />
        <mesh name="optimized/prohand_v18r_hand1_asy_v18_handr1_onefinger_sim1_finger_gen1801_proximal_gen181" file="optimized/prohand_v18r_hand1_asy_v18_handr1_onefinger_sim1_finger_gen1801_proximal_gen181.obj" />
        <mesh name="optimized/prohand_v18r_hand1_asy_v18_handr1_onefinger_sim1_finger_gen1801_metacarpal_gen181" file="optimized/prohand_v18r_hand1_asy_v18_handr1_onefinger_sim1_finger_gen1801_metacarpal_gen181.obj" />
        <mesh name="optimized/prohand_v18r_hand1_asy_v18_handr1_onefinger_sim2_finger_gen1801_distal_gen181" file="optimized/prohand_v18r_hand1_asy_v18_handr1_onefinger_sim2_finger_gen1801_distal_gen181.obj" />
        <mesh name="optimized/prohand_v18r_hand1_asy_v18_handr1_onefinger_sim2_finger_gen1801_medial_gen181" file="optimized/prohand_v18r_hand1_asy_v18_handr1_onefinger_sim2_finger_gen1801_medial_gen181.obj" />
        <mesh name="optimized/prohand_v18r_hand1_asy_v18_handr1_onefinger_sim2_finger_gen1801_proximal_gen181" file="optimized/prohand_v18r_hand1_asy_v18_handr1_onefinger_sim2_finger_gen1801_proximal_gen181.obj" />
        <mesh name="optimized/prohand_v18r_hand1_asy_v18_handr1_onefinger_sim2_finger_gen1801_metacarpal_gen181" file="optimized/prohand_v18r_hand1_asy_v18_handr1_onefinger_sim2_finger_gen1801_metacarpal_gen181.obj" />
        <mesh name="optimized/prohand_v18r_hand1_asy_v18_handr1_v17_hand_pinky1_proximal_body1" file="optimized/prohand_v18r_hand1_asy_v18_handr1_v17_hand_pinky1_proximal_body1.obj" />
        <mesh name="optimized/prohand_v18r_hand1_asy_v18_handr1_v17_hand_pinky1_middle_body1" file="optimized/prohand_v18r_hand1_asy_v18_handr1_v17_hand_pinky1_middle_body1.obj" />
        <mesh name="optimized/prohand_v18r_hand1_asy_v18_handr1_v17_hand_pinky1_distal_body1" file="optimized/prohand_v18r_hand1_asy_v18_handr1_v17_hand_pinky1_distal_body1.obj" />
        <mesh name="optimized/prohand_v18r_hand1_asy_v18_handr1_v17_hand_pinky1_metacarpal_base_link1" file="optimized/prohand_v18r_hand1_asy_v18_handr1_v17_hand_pinky1_metacarpal_base_link1.obj" />
        <mesh name="optimized/right_hand_wrist1_asy_prohand_v17_wrist_base_link1" file="optimized/right_hand_wrist1_asy_prohand_v17_wrist_base_link1.obj" />
        <mesh name="optimized/right_hand_wrist1_asy_prohand_v17_wrist_yaw_body1" file="optimized/right_hand_wrist1_asy_prohand_v17_wrist_yaw_body1.obj" />
        <mesh name="convex/right_forearm1" file="convex/right_forearm1.obj" />
        <mesh name="convex/prohand_v18r_hand1_asy_v18_handr1_rthumb_gen181_chassis_distal_thumb_gen161" file="convex/prohand_v18r_hand1_asy_v18_handr1_rthumb_gen181_chassis_distal_thumb_gen161.obj" />
        <mesh name="convex/prohand_v18r_hand1_asy_v18_handr1_rthumb_gen181_chassis_proximal_thumb_gen161" file="convex/prohand_v18r_hand1_asy_v18_handr1_rthumb_gen181_chassis_proximal_thumb_gen161.obj" />
        <mesh name="convex/prohand_v18r_hand1_asy_v18_handr1_rthumb_gen181_chassis_metacarpal_thumb_gen161" file="convex/prohand_v18r_hand1_asy_v18_handr1_rthumb_gen181_chassis_metacarpal_thumb_gen161.obj" />
        <mesh name="convex/prohand_v18r_hand1_asy_v18_handr1_rthumb_gen181_trapezium_thumb" file="convex/prohand_v18r_hand1_asy_v18_handr1_rthumb_gen181_trapezium_thumb.obj" />
        <mesh name="convex/prohand_v18r_hand1_asy_v18_handr1_rpalm_gen181_palm1" file="convex/prohand_v18r_hand1_asy_v18_handr1_rpalm_gen181_palm1.obj" />
        <mesh name="convex/prohand_v18r_hand1_asy_v18_handr1_onefinger_sim3_finger_gen1801_distal_gen181" file="convex/prohand_v18r_hand1_asy_v18_handr1_onefinger_sim3_finger_gen1801_distal_gen181.obj" />
        <mesh name="convex/prohand_v18r_hand1_asy_v18_handr1_onefinger_sim3_finger_gen1801_medial_gen181" file="convex/prohand_v18r_hand1_asy_v18_handr1_onefinger_sim3_finger_gen1801_medial_gen181.obj" />
        <mesh name="convex/prohand_v18r_hand1_asy_v18_handr1_onefinger_sim3_finger_gen1801_proximal_gen181" file="convex/prohand_v18r_hand1_asy_v18_handr1_onefinger_sim3_finger_gen1801_proximal_gen181.obj" />
        <mesh name="convex/prohand_v18r_hand1_asy_v18_handr1_onefinger_sim3_finger_gen1801_metacarpal_gen181" file="convex/prohand_v18r_hand1_asy_v18_handr1_onefinger_sim3_finger_gen1801_metacarpal_gen181.obj" />
        <mesh name="convex/prohand_v18r_hand1_asy_v18_handr1_onefinger_sim1_finger_gen1801_distal_gen181" file="convex/prohand_v18r_hand1_asy_v18_handr1_onefinger_sim1_finger_gen1801_distal_gen181.obj" />
        <mesh name="convex/prohand_v18r_hand1_asy_v18_handr1_onefinger_sim1_finger_gen1801_medial_gen181" file="convex/prohand_v18r_hand1_asy_v18_handr1_onefinger_sim1_finger_gen1801_medial_gen181.obj" />
        <mesh name="convex/prohand_v18r_hand1_asy_v18_handr1_onefinger_sim1_finger_gen1801_proximal_gen181" file="convex/prohand_v18r_hand1_asy_v18_handr1_onefinger_sim1_finger_gen1801_proximal_gen181.obj" />
        <mesh name="convex/prohand_v18r_hand1_asy_v18_handr1_onefinger_sim1_finger_gen1801_metacarpal_gen181" file="convex/prohand_v18r_hand1_asy_v18_handr1_onefinger_sim1_finger_gen1801_metacarpal_gen181.obj" />
        <mesh name="convex/prohand_v18r_hand1_asy_v18_handr1_onefinger_sim2_finger_gen1801_distal_gen181" file="convex/prohand_v18r_hand1_asy_v18_handr1_onefinger_sim2_finger_gen1801_distal_gen181.obj" />
        <mesh name="convex/prohand_v18r_hand1_asy_v18_handr1_onefinger_sim2_finger_gen1801_medial_gen181" file="convex/prohand_v18r_hand1_asy_v18_handr1_onefinger_sim2_finger_gen1801_medial_gen181.obj" />
        <mesh name="convex/prohand_v18r_hand1_asy_v18_handr1_onefinger_sim2_finger_gen1801_proximal_gen181" file="convex/prohand_v18r_hand1_asy_v18_handr1_onefinger_sim2_finger_gen1801_proximal_gen181.obj" />
        <mesh name="convex/prohand_v18r_hand1_asy_v18_handr1_onefinger_sim2_finger_gen1801_metacarpal_gen181" file="convex/prohand_v18r_hand1_asy_v18_handr1_onefinger_sim2_finger_gen1801_metacarpal_gen181.obj" />
        <mesh name="convex/prohand_v18r_hand1_asy_v18_handr1_v17_hand_pinky1_proximal_body1" file="convex/prohand_v18r_hand1_asy_v18_handr1_v17_hand_pinky1_proximal_body1.obj" />
        <mesh name="convex/prohand_v18r_hand1_asy_v18_handr1_v17_hand_pinky1_middle_body1" file="convex/prohand_v18r_hand1_asy_v18_handr1_v17_hand_pinky1_middle_body1.obj" />
        <mesh name="convex/prohand_v18r_hand1_asy_v18_handr1_v17_hand_pinky1_distal_body1" file="convex/prohand_v18r_hand1_asy_v18_handr1_v17_hand_pinky1_distal_body1.obj" />
        <mesh name="convex/prohand_v18r_hand1_asy_v18_handr1_v17_hand_pinky1_metacarpal_base_link1" file="convex/prohand_v18r_hand1_asy_v18_handr1_v17_hand_pinky1_metacarpal_base_link1.obj" />
        <mesh name="convex/right_hand_wrist1_asy_prohand_v17_wrist_base_link1" file="convex/right_hand_wrist1_asy_prohand_v17_wrist_base_link1.obj" />
        <mesh name="convex/right_hand_wrist1_asy_prohand_v17_wrist_yaw_body1" file="convex/right_hand_wrist1_asy_prohand_v17_wrist_yaw_body1.obj" />
    </asset>
    <worldbody>
        <body name="R/FOREARM1" pos="0.0000000 0.0000000 0.0000000" quat="1e+00 0e+00 0e+00 0e+00">
            <inertial mass="3.9427676" pos="0.0043528 0.0000449 0.1073299" diaginertia="1.526145e-02 1.522456e-02 4.313841e-03" />
            <geom name="R/FOREARM1/visual" class="visual" mesh="optimized/right_forearm1" />
            <geom name="R/FOREARM1/collision" class="collision" mesh="convex/right_forearm1" />
            <body name="R/wrist_base_(base_link)1" pos="0.0050000 0.0010000 0.2183000" quat="6.123e-17 -0e+00 0e+00 1e+00">
                <inertial mass="0.0598453" pos="0.0000027 0.0000166 0.0074329" diaginertia="7.91751e-06 1.003025e-05 1.142026e-05" />
                <geom name="R/wrist_base_(base_link)1/visual" class="visual" mesh="optimized/right_hand_wrist1_asy_prohand_v17_wrist_base_link1" />
                <geom name="R/wrist_base_(base_link)1/collision" class="collision" mesh="convex/right_hand_wrist1_asy_prohand_v17_wrist_base_link1" />
                <body name="R/Body1" pos="0.0000000 -0.0000000 0.0200000" quat="0e+00 7.071068e-01 0e+00 7.071068e-01">
                    <inertial mass="0.0893144" pos="0.0102605 0.0000213 0.0030975" diaginertia="2.136406e-05 1.967471e-05 2.998291e-05" />
                    <geom name="R/Body1/visual" class="visual" mesh="optimized/right_hand_wrist1_asy_prohand_v17_wrist_yaw_body1" />
                    <geom name="R/Body1/collision" class="collision" mesh="convex/right_hand_wrist1_asy_prohand_v17_wrist_yaw_body1" />
                    <joint name="R/wrist_yaw" axis="0 0 1" pos="0 0 0" range="-5.235988e-01 5.235988e-01" limited="true" />
                    <body name="R/Palm1" pos="0.0195000 0.0000000 0.0050000" quat="5e-01 5e-01 5e-01 -5e-01">
                        <inertial mass="0.7491704" pos="0.0002088 0.0516383 -0.0023448" diaginertia="1.025055e-03 4.307395e-04 7.16861e-04" />
                        <geom name="R/Palm1/visual" class="visual" mesh="optimized/prohand_v18r_hand1_asy_v18_handr1_rpalm_gen181_palm1" />
                        <geom name="R/Palm1/collision" class="collision" mesh="convex/prohand_v18r_hand1_asy_v18_handr1_rpalm_gen181_palm1" />
                        <joint name="R/wrist_pitch" axis="0 0 1" pos="0 0 0" range="-5.235988e-01 1.047198e+00" limited="true" />
                        <body name="R/metacarpal_base_(base_link)1" pos="-0.0010000 0.0930000 -0.0320000" quat="-7.071068e-01 -1.4943e-16 7.071068e-01 -4.7593e-16">
                            <inertial mass="0.0044634" pos="-0.0000002 0.0037355 -0.0003225" diaginertia="1.474219e-07 1.333687e-07 1.205535e-07" />
                            <geom name="R/metacarpal_base_(base_link)1/visual" class="visual" mesh="optimized/prohand_v18r_hand1_asy_v18_handr1_v17_hand_pinky1_metacarpal_base_link1" />
                            <geom name="R/metacarpal_base_(base_link)1/collision" class="collision" mesh="convex/prohand_v18r_hand1_asy_v18_handr1_v17_hand_pinky1_metacarpal_base_link1" />
                            <joint name="R/p0_CMC_abd" axis="0 0 1" pos="0 0 0" range="-6.108652e-01 2.617994e-01" limited="true" />
                            <body name="R/proximal_body1" pos="0.0000000 0.0070000 -0.0000120" quat="0e+00 7.071068e-01 0e+00 7.071068e-01">
                                <inertial mass="0.0210231" pos="0.0030714 -0.0174744 -0.0000006" diaginertia="1.47529e-06 9.286679e-07 1.244961e-06" />
                                <geom name="R/proximal_body1/visual" class="visual" mesh="optimized/prohand_v18r_hand1_asy_v18_handr1_v17_hand_pinky1_proximal_body1" />
                                <geom name="R/proximal_body1/collision" class="collision" mesh="convex/prohand_v18r_hand1_asy_v18_handr1_v17_hand_pinky1_proximal_body1" />
                                <joint name="R/p1_MCP" axis="0 0 1" pos="0 0 0" range="-3.490658e-01 1.570796e+00" limited="true" />
                                <body name="R/middle_body1" pos="0.0000000 -0.0320000 -0.0000000" quat="1e+00 1.3796e-16 -1.1102e-16 -4e-20">
                                    <inertial mass="0.0050835" pos="0.0018313 -0.0112756 -0.0000000" diaginertia="3.539997e-07 1.518711e-07 3.039656e-07" />
                                    <geom name="R/middle_body1/visual" class="visual" mesh="optimized/prohand_v18r_hand1_asy_v18_handr1_v17_hand_pinky1_middle_body1" />
                                    <geom name="R/middle_body1/collision" class="collision" mesh="convex/prohand_v18r_hand1_asy_v18_handr1_v17_hand_pinky1_middle_body1" />
                                    <joint name="R/p2_PIP" axis="0 0 1" pos="0 0 0" range="-2.617994e-01 1.570796e+00" limited="true" />
                                    <body name="R/distal_body1" pos="0.0040000 -0.0200000 -0.0000000" quat="1e+00 2.963e-17 0e+00 -1.384e-17">
                                        <inertial mass="0.0059230" pos="-0.0016616 -0.0128501 0.0000005" diaginertia="4.257244e-07 1.446234e-07 4.098516e-07" />
                                        <geom name="R/distal_body1/visual" class="visual" mesh="optimized/prohand_v18r_hand1_asy_v18_handr1_v17_hand_pinky1_distal_body1" />
                                        <geom name="R/distal_body1/collision" class="collision" mesh="convex/prohand_v18r_hand1_asy_v18_handr1_v17_hand_pinky1_distal_body1" />
                                        <joint name="R/p3_DIP" axis="0 0 1" pos="0 0 0" range="0e+00 1.570796e+00" limited="true" />
                                    </body>
                                </body>
                            </body>
                        </body>
                        <body name="R/THUMB" pos="-0.0100000 0.0395289 0.0235680" quat="1.59712e-15 -1.87099e-15 -5.735764e-01 8.19152e-01">
                            <inertial mass="0.0231931" pos="-0.0005379 -0.0028578 -0.0008761" diaginertia="1.870542e-06 1.614859e-06 1.25586e-06" />
                            <geom name="R/THUMB/visual" class="visual" mesh="optimized/prohand_v18r_hand1_asy_v18_handr1_rthumb_gen181_trapezium_thumb" />
                            <geom name="R/THUMB/collision" class="collision" mesh="convex/prohand_v18r_hand1_asy_v18_handr1_rthumb_gen181_trapezium_thumb" />
                            <joint name="R/t0_TM_abd" axis="0 0 1" pos="0 0 0" range="0e+00 2.094395e+00" limited="true" />
                            <body name="R/METACARPAL_THUMB_GEN161" pos="-0.0000000 -0.0100000 0.0010000" quat="5e-01 -5e-01 5e-01 -5e-01">
                                <inertial mass="0.0657326" pos="0.0128147 0.0015230 0.0006213" diaginertia="6.943868e-06 6.560442e-06 7.766798e-06" />
                                <geom name="R/METACARPAL_THUMB_GEN161/visual" class="visual" mesh="optimized/prohand_v18r_hand1_asy_v18_handr1_rthumb_gen181_chassis_metacarpal_thumb_gen161" />
                                <geom name="R/METACARPAL_THUMB_GEN161/collision" class="collision" mesh="convex/prohand_v18r_hand1_asy_v18_handr1_rthumb_gen181_chassis_metacarpal_thumb_gen161" />
                                <joint name="R/t1_TM" axis="0 0 1" pos="0 0 0" range="-3.490658e-01 1.047198e+00" limited="true" />
                                <body name="R/PROXIMAL_THUMB_GEN161" pos="0.0250000 0.0000000 -0.0000000" quat="7.010574e-01 9.229596e-02 9.229596e-02 -7.010574e-01">
                                    <inertial mass="0.0399139" pos="0.0001981 0.0165019 0.0001321" diaginertia="4.471779e-06 2.049638e-06 4.560039e-06" />
                                    <geom name="R/PROXIMAL_THUMB_GEN161/visual" class="visual" mesh="optimized/prohand_v18r_hand1_asy_v18_handr1_rthumb_gen181_chassis_proximal_thumb_gen161" />
                                    <geom name="R/PROXIMAL_THUMB_GEN161/collision" class="collision" mesh="convex/prohand_v18r_hand1_asy_v18_handr1_rthumb_gen181_chassis_proximal_thumb_gen161" />
                                    <joint name="R/t2_CMC" axis="0 0 1" pos="0 0 0" range="-3.490658e-01 1.570796e+00" limited="true" />
                                    <body name="R/DISTAL_THUMB_GEN161" pos="0.0000000 0.0320000 0.0000000" quat="1e+00 2.89313e-15 1.48492e-15 1.495e-17">
                                        <inertial mass="0.0469449" pos="-0.0012187 0.0158772 -0.0000500" diaginertia="4.630198e-06 1.888133e-06 4.643791e-06" />
                                        <geom name="R/DISTAL_THUMB_GEN161/visual" class="visual" mesh="optimized/prohand_v18r_hand1_asy_v18_handr1_rthumb_gen181_chassis_distal_thumb_gen161" />
                                        <geom name="R/DISTAL_THUMB_GEN161/collision" class="collision" mesh="convex/prohand_v18r_hand1_asy_v18_handr1_rthumb_gen181_chassis_distal_thumb_gen161" />
                                        <joint name="R/t3_DIP" axis="0 0 1" pos="0 0 0" range="-3.490658e-01 1.570796e+00" limited="true" />
                                    </body>
                                </body>
                            </body>
                        </body>
                        <body name="R/SIM1_FINGER_GEN1801_METACARPAL_GEN181" pos="-0.0010000 0.1080000 0.0100000" quat="-7.071068e-01 -1.4943e-16 7.071068e-01 -4.7593e-16">
                            <inertial mass="0.0107395" pos="-0.0000014 0.0028816 -0.0003086" diaginertia="3.780428e-07 3.721189e-07 3.020315e-07" />
                            <geom name="R/SIM1_FINGER_GEN1801_METACARPAL_GEN181/visual" class="visual" mesh="optimized/prohand_v18r_hand1_asy_v18_handr1_onefinger_sim1_finger_gen1801_metacarpal_gen181" />
                            <geom name="R/SIM1_FINGER_GEN1801_METACARPAL_GEN181/collision" class="collision" mesh="convex/prohand_v18r_hand1_asy_v18_handr1_onefinger_sim1_finger_gen1801_metacarpal_gen181" />
                            <joint name="R/m0_CMC_abd" axis="0 0 1" pos="0 0 0" range="-2.617994e-01 2.617994e-01" limited="true" />
                            <body name="R/SIM1_FINGER_GEN1801_PROXIMAL_GEN181" pos="0.0000000 0.0070000 -0.0000120" quat="0e+00 7.071068e-01 0e+00 7.071068e-01">
                                <inertial mass="0.0531353" pos="0.0027207 -0.0228719 0.0000000" diaginertia="7.274961e-06 2.192604e-06 6.663851e-06" />
                                <geom name="R/SIM1_FINGER_GEN1801_PROXIMAL_GEN181/visual" class="visual" mesh="optimized/prohand_v18r_hand1_asy_v18_handr1_onefinger_sim1_finger_gen1801_proximal_gen181" />
                                <geom name="R/SIM1_FINGER_GEN1801_PROXIMAL_GEN181/collision" class="collision" mesh="convex/prohand_v18r_hand1_asy_v18_handr1_onefinger_sim1_finger_gen1801_proximal_gen181" />
                                <joint name="R/m1_MCP" axis="0 0 1" pos="0 0 0" range="-3.490658e-01 1.570796e+00" limited="true" />
                                <body name="R/SIM1_FINGER_GEN1801_MEDIAL_GEN181" pos="-0.0000000 -0.0420000 -0.0000000" quat="1e+00 -1.744e-17 0e+00 -4.597e-17">
                                    <inertial mass="0.0235649" pos="0.0012835 -0.0130121 0.0000000" diaginertia="1.461732e-06 7.296005e-07 1.214972e-06" />
                                    <geom name="R/SIM1_FINGER_GEN1801_MEDIAL_GEN181/visual" class="visual" mesh="optimized/prohand_v18r_hand1_asy_v18_handr1_onefinger_sim1_finger_gen1801_medial_gen181" />
                                    <geom name="R/SIM1_FINGER_GEN1801_MEDIAL_GEN181/collision" class="collision" mesh="convex/prohand_v18r_hand1_asy_v18_handr1_onefinger_sim1_finger_gen1801_medial_gen181" />
                                    <joint name="R/m2_PIP" axis="0 0 1" pos="0 0 0" range="-3.490658e-01 1.570796e+00" limited="true" />
                                    <body name="R/SIM1_FINGER_GEN1801_DISTAL_GEN181" pos="0.0040000 -0.0200000 -0.0000000" quat="1e+00 3.4056e-16 -2.7756e-16 -8.587e-17">
                                        <inertial mass="0.0294935" pos="-0.0020998 -0.0143962 -0.0000000" diaginertia="1.978919e-06 8.210773e-07 1.822869e-06" />
                                        <geom name="R/SIM1_FINGER_GEN1801_DISTAL_GEN181/visual" class="visual" mesh="optimized/prohand_v18r_hand1_asy_v18_handr1_onefinger_sim1_finger_gen1801_distal_gen181" />
                                        <geom name="R/SIM1_FINGER_GEN1801_DISTAL_GEN181/collision" class="collision" mesh="convex/prohand_v18r_hand1_asy_v18_handr1_onefinger_sim1_finger_gen1801_distal_gen181" />
                                        <joint name="R/m3_DIP" axis="0 0 1" pos="0 0 0" range="0e+00 1.570796e+00" limited="true" />
                                    </body>
                                </body>
                            </body>
                        </body>
                        <body name="R/SIM2_FINGER_GEN1801_METACARPAL_GEN181" pos="-0.0010000 0.0980000 0.0310000" quat="-7.071068e-01 -1.4943e-16 7.071068e-01 -4.7593e-16">
                            <inertial mass="0.0107395" pos="-0.0000014 0.0028816 -0.0003086" diaginertia="3.780428e-07 3.721189e-07 3.020315e-07" />
                            <geom name="R/SIM2_FINGER_GEN1801_METACARPAL_GEN181/visual" class="visual" mesh="optimized/prohand_v18r_hand1_asy_v18_handr1_onefinger_sim2_finger_gen1801_metacarpal_gen181" />
                            <geom name="R/SIM2_FINGER_GEN1801_METACARPAL_GEN181/collision" class="collision" mesh="convex/prohand_v18r_hand1_asy_v18_handr1_onefinger_sim2_finger_gen1801_metacarpal_gen181" />
                            <joint name="R/i0_CMC_abd" axis="0 0 1" pos="0 0 0" range="-2.617994e-01 6.108652e-01" limited="true" />
                            <body name="R/SIM2_FINGER_GEN1801_PROXIMAL_GEN181" pos="0.0000000 0.0070000 -0.0000120" quat="0e+00 7.071068e-01 0e+00 7.071068e-01">
                                <inertial mass="0.0531353" pos="0.0027207 -0.0228719 0.0000000" diaginertia="7.274961e-06 2.192604e-06 6.663851e-06" />
                                <geom name="R/SIM2_FINGER_GEN1801_PROXIMAL_GEN181/visual" class="visual" mesh="optimized/prohand_v18r_hand1_asy_v18_handr1_onefinger_sim2_finger_gen1801_proximal_gen181" />
                                <geom name="R/SIM2_FINGER_GEN1801_PROXIMAL_GEN181/collision" class="collision" mesh="convex/prohand_v18r_hand1_asy_v18_handr1_onefinger_sim2_finger_gen1801_proximal_gen181" />
                                <joint name="R/i1_MCP" axis="0 0 1" pos="0 0 0" range="-3.490658e-01 1.570796e+00" limited="true" />
                                <body name="R/SIM2_FINGER_GEN1801_MEDIAL_GEN181" pos="-0.0000000 -0.0420000 -0.0000000" quat="1e+00 -1.744e-17 0e+00 -4.597e-17">
                                    <inertial mass="0.0235649" pos="0.0012835 -0.0130121 0.0000000" diaginertia="1.461732e-06 7.296005e-07 1.214972e-06" />
                                    <geom name="R/SIM2_FINGER_GEN1801_MEDIAL_GEN181/visual" class="visual" mesh="optimized/prohand_v18r_hand1_asy_v18_handr1_onefinger_sim2_finger_gen1801_medial_gen181" />
                                    <geom name="R/SIM2_FINGER_GEN1801_MEDIAL_GEN181/collision" class="collision" mesh="convex/prohand_v18r_hand1_asy_v18_handr1_onefinger_sim2_finger_gen1801_medial_gen181" />
                                    <joint name="R/i2_PIP" axis="0 0 1" pos="0 0 0" range="-3.490658e-01 1.570796e+00" limited="true" />
                                    <body name="R/SIM2_FINGER_GEN1801_DISTAL_GEN181" pos="0.0040000 -0.0200000 -0.0000000" quat="1e+00 3.4056e-16 -2.7756e-16 -8.587e-17">
                                        <inertial mass="0.0294935" pos="-0.0020998 -0.0143962 -0.0000000" diaginertia="1.978919e-06 8.210773e-07 1.822869e-06" />
                                        <geom name="R/SIM2_FINGER_GEN1801_DISTAL_GEN181/visual" class="visual" mesh="optimized/prohand_v18r_hand1_asy_v18_handr1_onefinger_sim2_finger_gen1801_distal_gen181" />
                                        <geom name="R/SIM2_FINGER_GEN1801_DISTAL_GEN181/collision" class="collision" mesh="convex/prohand_v18r_hand1_asy_v18_handr1_onefinger_sim2_finger_gen1801_distal_gen181" />
                                        <joint name="R/i3_DIP" axis="0 0 1" pos="0 0 0" range="0e+00 1.570796e+00" limited="true" />
                                    </body>
                                </body>
                            </body>
                        </body>
                        <body name="R/SIM3_FINGER_GEN1801_METACARPAL_GEN181" pos="-0.0010000 0.0980000 -0.0110000" quat="-7.071068e-01 -1.4943e-16 7.071068e-01 -4.7593e-16">
                            <inertial mass="0.0107395" pos="-0.0000014 0.0028816 -0.0003086" diaginertia="3.780428e-07 3.721189e-07 3.020315e-07" />
                            <geom name="R/SIM3_FINGER_GEN1801_METACARPAL_GEN181/visual" class="visual" mesh="optimized/prohand_v18r_hand1_asy_v18_handr1_onefinger_sim3_finger_gen1801_metacarpal_gen181" />
                            <geom name="R/SIM3_FINGER_GEN1801_METACARPAL_GEN181/collision" class="collision" mesh="convex/prohand_v18r_hand1_asy_v18_handr1_onefinger_sim3_finger_gen1801_metacarpal_gen181" />
                            <joint name="R/r0_CMC_abd" axis="0 0 1" pos="0 0 0" range="-2.617994e-01 2.617994e-01" limited="true" />
                            <body name="R/SIM3_FINGER_GEN1801_PROXIMAL_GEN181" pos="0.0000000 0.0070000 -0.0000120" quat="0e+00 7.071068e-01 0e+00 7.071068e-01">
                                <inertial mass="0.0531353" pos="0.0027207 -0.0228719 0.0000000" diaginertia="7.274961e-06 2.192604e-06 6.663851e-06" />
                                <geom name="R/SIM3_FINGER_GEN1801_PROXIMAL_GEN181/visual" class="visual" mesh="optimized/prohand_v18r_hand1_asy_v18_handr1_onefinger_sim3_finger_gen1801_proximal_gen181" />
                                <geom name="R/SIM3_FINGER_GEN1801_PROXIMAL_GEN181/collision" class="collision" mesh="convex/prohand_v18r_hand1_asy_v18_handr1_onefinger_sim3_finger_gen1801_proximal_gen181" />
                                <joint name="R/r1_MCP" axis="0 0 1" pos="0 0 0" range="-3.490658e-01 1.570796e+00" limited="true" />
                                <body name="R/SIM3_FINGER_GEN1801_MEDIAL_GEN181" pos="-0.0000000 -0.0420000 -0.0000000" quat="1e+00 -1.744e-17 0e+00 -4.597e-17">
                                    <inertial mass="0.0235649" pos="0.0012835 -0.0130121 0.0000000" diaginertia="1.461732e-06 7.296005e-07 1.214972e-06" />
                                    <geom name="R/SIM3_FINGER_GEN1801_MEDIAL_GEN181/visual" class="visual" mesh="optimized/prohand_v18r_hand1_asy_v18_handr1_onefinger_sim3_finger_gen1801_medial_gen181" />
                                    <geom name="R/SIM3_FINGER_GEN1801_MEDIAL_GEN181/collision" class="collision" mesh="convex/prohand_v18r_hand1_asy_v18_handr1_onefinger_sim3_finger_gen1801_medial_gen181" />
                                    <joint name="R/r2_PIP" axis="0 0 1" pos="0 0 0" range="-3.490658e-01 1.570796e+00" limited="true" />
                                    <body name="R/SIM3_FINGER_GEN1801_DISTAL_GEN181" pos="0.0040000 -0.0200000 -0.0000000" quat="1e+00 3.4056e-16 -2.7756e-16 -8.587e-17">
                                        <inertial mass="0.0294935" pos="-0.0020998 -0.0143962 -0.0000000" diaginertia="1.978919e-06 8.210773e-07 1.822869e-06" />
                                        <geom name="R/SIM3_FINGER_GEN1801_DISTAL_GEN181/visual" class="visual" mesh="optimized/prohand_v18r_hand1_asy_v18_handr1_onefinger_sim3_finger_gen1801_distal_gen181" />
                                        <geom name="R/SIM3_FINGER_GEN1801_DISTAL_GEN181/collision" class="collision" mesh="convex/prohand_v18r_hand1_asy_v18_handr1_onefinger_sim3_finger_gen1801_distal_gen181" />
                                        <joint name="R/r3_DIP" axis="0 0 1" pos="0 0 0" range="0e+00 1.570796e+00" limited="true" />
                                    </body>
                                </body>
                            </body>
                        </body>
                    </body>
                </body>
            </body>
        </body>
    </worldbody>
</mujoco>